<?xml version="1.0" encoding="utf-8"?>
 <robot name='my_robot'>
    <link name="base_link">      
      <inertial>
      <origin xyz="-0.151427 0 0.175" rpy="0 -0 0"/>
        <mass value="1.14395"/>
        <inertia
          ixx="0.126164"
          ixy="0"
          ixz="0"
          iyy="0.416519"
          iyz="0"
          izz="0.481014"
        />
     
      </inertial>
      <visual>
      <origin
        xyz="0 0 0"
        rpy="0 0 0" />
        <geometry>
          <box size="2.01142 1 0.568726"/>
        </geometry>
        <material
        name="">
        <color
          rgba="0.792156862745098 0.819607843137255 0.933333333333333 1" />
      </material>
      </visual>
      <collision>
      <origin
        xyz="0 0 0"
        rpy="0 0 0" />
        
        <geometry>
          <box size="2.01142 1 0.568726"/>
        </geometry>
      </collision>
    </link>
    
    
    <link name='right_wheel'>
    <inertial>
      <origin xyz="0.554282 -0.625029 -0.025" rpy=" -1.5707 -0 -0"/>
        <mass value="2"/>
        <inertia
          ixx="0.145833"
          ixy="0"
          ixz="0"
          iyy="0.145833"
          iyz="0"
          izz="0.125"
        />
     
      </inertial>
      <visual>
      <origin
        xyz="0 0 0"
        rpy="0 0 0" />
        <geometry>
          <sphere radius="0.3"/>
          
        </geometry>
        <material
        name="">
        <color
          rgba="0.792156862745098 0.819607843137255 0.933333333333333 1" />
      </material>
      </visual>
      <collision>
      <origin
        xyz="0 0 0"
        rpy="0 0 0" />        
        <geometry>
          <sphere radius="0.3"/>
        </geometry>
      </collision>
    </link>
    
    <joint name='right_wheel_joint' type='revolute'>
      <parent link="base_link"/>
      <child link="right_wheel"/>
      <origin xyz="0.554282 -0.625029 -0.025" rpy=" 0 -0 0"/>
      <axis xyz="0 0 1"/>
        <limit lower="-1.79769e+308" upper="1.79769e+308" effort="-1" velocity="-1"/>
    </joint>   
    
    <link name='left_wheel'>
    <inertial>
      <origin xyz="0.554283 0.625029 -0.025" rpy="-1.5707 -0 -0"/>
        <mass value="2"/>
        <inertia
          ixx="0.145833"
          ixy="0"
          ixz="0"
          iyy="0.145833"
          iyz="0"
          izz="0.125"
        />
     
      </inertial>
      <visual>
      <origin
        xyz="0 0 0"
        rpy="0 0 0" />
        <geometry>
          <sphere radius="0.3"/>
        </geometry>
        <material
        name="">
        <color
          rgba="0.792156862745098 0.819607843137255 0.933333333333333 1" />
      </material>
      </visual>
      <collision>
      <origin
        xyz="0 0 0"
        rpy="0 0 0" />
        
        <geometry>
          <sphere radius="0.3"/>
        </geometry>
      </collision>
    </link>
    <joint name='left_wheel_joint' type='revolute'>
      <parent link="base_link"/>
      <child link="left_wheel"/>
      <origin xyz="0.554283 0.625029 -0.025" rpy=" 0 -0 0"/>
      <axis xyz="0 0 1"/>
        <limit lower="-1.79769e+308" upper="1.79769e+308" effort="-1" velocity="-1"/>
    </joint>
    
</robot>
