<sdf version='1.7'>
  <model name='my_robot'>
    <link name='base_link'>
      <inertial>
        <pose>-0.106265 0.0021 -0.014236 0 -0 0</pose>
        <mass>144.436</mass>
        <inertia>
          <ixx>2.66112</ixx>
          <ixy>4.34784e-05</ixy>
          <ixz>1.41234</ixz>
          <iyy>37.2151</iyy>
          <iyz>1.50741e-05</iyz>
          <izz>38.2736</izz>
        </inertia>
      </inertial>
      <collision name='base_link_collision'>
        <pose>0 0 0 0 -0 0</pose>
        <geometry>
          <mesh>
            <scale>1 1 1</scale>
            <uri>model://my_robot/meshes/base_link.STL</uri>
          </mesh>
        </geometry>
      </collision>
      <visual name='base_link_visual'>
        <pose>0 0 0 0 -0 0</pose>
        <geometry>
          <mesh>
            <scale>1 1 1</scale>
            <uri>model://my_robot/meshes/base_link.STL</uri>
          </mesh>
        </geometry>
      </visual>
    </link>
    <joint name='back_left_wheel_joint' type='revolute'>
      <pose relative_to='base_link'>-0.82 0.34 -0.031041 0 -0 0</pose>
      <parent>base_link</parent>
      <child>back_left_wheel</child>
      <axis>
        <xyz>0 1 0</xyz>
        <limit>
          <lower>-1e+16</lower>
          <upper>1e+16</upper>
        </limit>
        <dynamics>
          <spring_reference>0</spring_reference>
          <spring_stiffness>0</spring_stiffness>
        </dynamics>
      </axis>
    </joint>
    <link name='back_left_wheel'>
      <pose relative_to='back_left_wheel_joint'>0 0 0 0 -0 0</pose>
      <inertial>
        <pose>-0 0.020554 -0 0 -0 0</pose>
        <mass>10.426</mass>
        <inertia>
          <ixx>0.064119</ixx>
          <ixy>3.8659e-18</ixy>
          <ixz>-7.1542e-17</ixz>
          <iyy>0.11102</iyy>
          <iyz>-5.3112e-16</iyz>
          <izz>0.064119</izz>
        </inertia>
      </inertial>
      <collision name='back_left_wheel_collision'>
        <pose>0 0 0 0 -0 0</pose>
        <geometry>
          <mesh>
            <scale>1 1 1</scale>
            <uri>model://my_robot/meshes/back_left_wheel.STL</uri>
          </mesh>
        </geometry>
      </collision>
      <visual name='back_left_wheel_visual'>
        <pose>0 0 0 0 -0 0</pose>
        <geometry>
          <mesh>
            <scale>1 1 1</scale>
            <uri>model://my_robot/meshes/back_left_wheel.STL</uri>
          </mesh>
        </geometry>
      </visual>
    </link>
    <joint name='back_right_wheel_joint' type='revolute'>
      <pose relative_to='base_link'>-0.82 -0.3358 -0.031041 0 -0 0</pose>
      <parent>base_link</parent>
      <child>back_right_wheel</child>
      <axis>
        <xyz>0 1 0</xyz>
        <limit>
          <lower>-1e+16</lower>
          <upper>1e+16</upper>
        </limit>
        <dynamics>
          <spring_reference>0</spring_reference>
          <spring_stiffness>0</spring_stiffness>
        </dynamics>
      </axis>
    </joint>
    <link name='back_right_wheel'>
      <pose relative_to='back_right_wheel_joint'>0 0 0 0 -0 0</pose>
      <inertial>
        <pose>-0 -0.020554 -0 0 -0 0</pose>
        <mass>10.426</mass>
        <inertia>
          <ixx>0.064119</ixx>
          <ixy>9.9658e-18</ixy>
          <ixz>-7.0799e-17</ixz>
          <iyy>0.11102</iyy>
          <iyz>1.7217e-18</iyz>
          <izz>0.064119</izz>
        </inertia>
      </inertial>
      <collision name='back_right_wheel_collision'>
        <pose>0 0 0 0 -0 0</pose>
        <geometry>
          <mesh>
            <scale>1 1 1</scale>
            <uri>model://my_robot/meshes/back_right_wheel.STL</uri>
          </mesh>
        </geometry>
      </collision>
      <visual name='back_right_wheel_visual'>
        <pose>0 0 0 0 -0 0</pose>
        <geometry>
          <mesh>
            <scale>1 1 1</scale>
            <uri>model://my_robot/meshes/back_right_wheel.STL</uri>
          </mesh>
        </geometry>
      </visual>
    </link>
    <joint name='front_left_wheel_joint' type='revolute'>
      <pose relative_to='base_link'>0.2176 0.34 -0.031041 0 -0 0</pose>
      <parent>base_link</parent>
      <child>front_left_wheel</child>
      <axis>
        <xyz>0 1 0</xyz>
        <limit>
          <lower>-1e+16</lower>
          <upper>1e+16</upper>
        </limit>
        <dynamics>
          <spring_reference>0</spring_reference>
          <spring_stiffness>0</spring_stiffness>
        </dynamics>
      </axis>
    </joint>
    <link name='front_left_wheel'>
      <pose relative_to='front_left_wheel_joint'>0 0 0 0 -0 0</pose>
      <inertial>
        <pose>-0 0.020554 -0 0 -0 0</pose>
        <mass>10.426</mass>
        <inertia>
          <ixx>0.064119</ixx>
          <ixy>-3.7701e-19</ixy>
          <ixz>2.0432e-17</ixz>
          <iyy>0.11102</iyy>
          <iyz>-5.225e-16</iyz>
          <izz>0.064119</izz>
        </inertia>
      </inertial>
      <collision name='front_left_wheel_collision'>
        <pose>0 0 0 0 -0 0</pose>
        <geometry>
          <mesh>
            <scale>1 1 1</scale>
            <uri>model://my_robot/meshes/front_left_wheel.STL</uri>
          </mesh>
        </geometry>
      </collision>
      <visual name='front_left_wheel_visual'>
        <pose>0 0 0 0 -0 0</pose>
        <geometry>
          <mesh>
            <scale>1 1 1</scale>
            <uri>model://my_robot/meshes/front_left_wheel.STL</uri>
          </mesh>
        </geometry>
      </visual>
    </link>
    <joint name='front_right_wheel_joint' type='revolute'>
      <pose relative_to='base_link'>0.2176 -0.3358 -0.031041 0 -0 0</pose>
      <parent>base_link</parent>
      <child>front_right_wheel</child>
      <axis>
        <xyz>0 1 0</xyz>
        <limit>
          <lower>-1e+16</lower>
          <upper>1e+16</upper>
        </limit>
        <dynamics>
          <spring_reference>0</spring_reference>
          <spring_stiffness>0</spring_stiffness>
        </dynamics>
      </axis>
    </joint>
    <link name='front_right_wheel'>
      <pose relative_to='front_right_wheel_joint'>0 0 0 0 -0 0</pose>
      <inertial>
        <pose>-0 -0.020554 -0 0 -0 0</pose>
        <mass>10.426</mass>
        <inertia>
          <ixx>0.064119</ixx>
          <ixy>8.339e-18</ixy>
          <ixz>-6.9613e-17</ixz>
          <iyy>0.11102</iyy>
          <iyz>-5.6072e-19</iyz>
          <izz>0.064119</izz>
        </inertia>
      </inertial>
      <collision name='front_right_wheel_collision'>
        <pose>0 0 0 0 -0 0</pose>
        <geometry>
          <mesh>
            <scale>1 1 1</scale>
            <uri>model://my_robot/meshes/front_right_wheel.STL</uri>
          </mesh>
        </geometry>
      </collision>
      <visual name='front_right_wheel_visual'>
        <pose>0 0 0 0 -0 0</pose>
        <geometry>
          <mesh>
            <scale>1 1 1</scale>
            <uri>model://my_robot/meshes/front_right_wheel.STL</uri>
          </mesh>
        </geometry>
      </visual>
    </link>
    <joint name='lidar_link_joint' type='fixed'>
      <pose relative_to='base_link'>0.15965 0.0021 0.1103 0 -0 0</pose>
      <parent>base_link</parent>
      <child>lidar_link</child>
      <axis>
        <dynamics>
          <spring_reference>0</spring_reference>
          <spring_stiffness>0</spring_stiffness>
        </dynamics>
        <xyz>0 0 1</xyz>
        <limit>
          <lower>-1e+16</lower>
          <upper>1e+16</upper>
        </limit>
      </axis>
      <physics>
        <ode>
          <limit>
            <cfm>0</cfm>
            <erp>0.2</erp>
          </limit>
        </ode>
      </physics>
    </joint>
    <link name='lidar_link'>
      <pose relative_to='lidar_link_joint'>0 0 0 0 -0 0</pose>
      <inertial>
        <pose>-0.000277 -0 0.005 0 -0 0</pose>
        <mass>0.016141</mass>
        <inertia>
          <ixx>4.2235e-06</ixx>
          <ixy>-1.9485e-22</ixy>
          <ixz>3.4687e-23</ixz>
          <iyy>7.0432e-07</iyy>
          <iyz>2.1281e-23</iyz>
          <izz>4.6511e-06</izz>
        </inertia>
      </inertial>
      <collision name='lidar_link_collision'>
        <pose>0 0 0 0 -0 0</pose>
        <geometry>
          <mesh>
            <scale>1 1 1</scale>
            <uri>model://my_robot/meshes/lidar_link.STL</uri>
          </mesh>
        </geometry>
        <surface>
          <contact>
            <ode/>
          </contact>
          <friction>
            <ode/>
          </friction>
        </surface>
      </collision>
      <visual name='lidar_link_visual'>
        <pose>0 0 0 0 -0 0</pose>
        <geometry>
          <mesh>
            <scale>1 1 1</scale>
            <uri>model://my_robot/meshes/lidar_link.STL</uri>
          </mesh>
        </geometry>
      </visual>
      <gravity>1</gravity>
      <velocity_decay/>
      <sensor name='ray_sensor' type='ray'>
        <visualize>1</visualize>
        <ray>
          <scan>
            <horizontal>
              <samples>40</samples>
              <resolution>1</resolution>
              <min_angle>-0.698132</min_angle>
              <max_angle>0.698132</max_angle>
            </horizontal>
          </scan>
          <range>
            <min>0.81</min>
            <max>50</max>
          </range>
        </ray>
        <plugin name='lidar_controller' filename='libgazebo_ros_laser.so'>
          <alwaysOn>1</alwaysOn>
          <updateRate>30</updateRate>
          <topicName>base_scan</topicName>
          <frameName>lidar_link</frameName>
        </plugin>
        <always_on>1</always_on>
        <update_rate>1</update_rate>
        <parent link='lidar_link'/>
      </sensor>
    </link>
    <joint name='camera_link_joint' type='fixed'>
      <pose relative_to='lidar_link'>0 0 0.01 0 -0 0</pose>
      <parent>lidar_link</parent>
      <child>camera_link</child>
      <axis>
        <dynamics>
          <spring_reference>0</spring_reference>
          <spring_stiffness>0</spring_stiffness>
        </dynamics>
        <xyz>0 0 1</xyz>
        <limit>
          <lower>-1e+16</lower>
          <upper>1e+16</upper>
        </limit>
      </axis>
      <physics>
        <ode>
          <limit>
            <cfm>0</cfm>
            <erp>0.2</erp>
          </limit>
        </ode>
      </physics>
    </joint>
    <link name='camera_link'>
      <pose relative_to='camera_link_joint'>0 0 0 0 -0 0</pose>
      <inertial>
        <pose>-0.000277 -0 0.005 0 -0 0</pose>
        <mass>0.016141</mass>
        <inertia>
          <ixx>4.2235e-06</ixx>
          <ixy>-1.9711e-22</ixy>
          <ixz>-3.677e-23</ixz>
          <iyy>7.0432e-07</iyy>
          <iyz>-1.4426e-22</iyz>
          <izz>4.6511e-06</izz>
        </inertia>
      </inertial>
      <collision name='camera_link_collision'>
        <pose>0 0 0 0 -0 0</pose>
        <geometry>
          <mesh>
            <scale>1 1 1</scale>
            <uri>model://my_robot/meshes/camera_link.STL</uri>
          </mesh>
        </geometry>
        <surface>
          <contact>
            <ode/>
          </contact>
          <friction>
            <ode/>
          </friction>
        </surface>
      </collision>
      <visual name='camera_link_visual'>
        <pose>0 0 0 0 -0 0</pose>
        <geometry>
          <mesh>
            <scale>1 1 1</scale>
            <uri>model://my_robot/meshes/camera_link.STL</uri>
          </mesh>
        </geometry>
      </visual>
      <gravity>1</gravity>
      <velocity_decay/>
      <sensor name='camera_sensor' type='camera'>
        <update_rate>30</update_rate>
        <visualize>1</visualize>
        <camera>
          <horizontal_fov>1.39626</horizontal_fov>
          <image>
            <format>R8G8B8</format>
            <width>640</width>
            <height>480</height>
          </image>
          <clip>
            <near>0.81</near>
            <far>50</far>
          </clip>
        </camera>
        <plugin name='camera_controller' filename='libgazebo_ros_camera.so'>
          <cameraName>front_camera</cameraName>
          <alwaysOn>1</alwaysOn>
          <updateRate>0.0</updateRate>
          <imageTopicName>image_raw</imageTopicName>
          <cameraInfoTopicName>camera_info</cameraInfoTopicName>
          <frameName>camera_link</frameName>
        </plugin>
        <parent link='camera_link'/>
      </sensor>
    </link>
    <static>0</static>
    <plugin name='skid_drive_controller' filename='libgazebo_ros_skid_steer_drive.so'>
      <updateRate>100.0</updateRate>
      <robotNamespace>/my_robot</robotNamespace>
      <commandTopic>cmd_vel</commandTopic>
      <torque>50</torque>
      <leftFrontJoint>front_left_wheel_joint</leftFrontJoint>
      <rightFrontJoint>front_right_wheel_joint</rightFrontJoint>
      <leftRearJoint>back_left_wheel_joint</leftRearJoint>
      <rightRearJoint>back_right_wheel_joint</rightRearJoint>
      <wheelSeparation>0.72</wheelSeparation>
      <wheelDiameter>0.28</wheelDiameter>
      <wheelAcceleration>1.0</wheelAcceleration>
      <odometryTopic>odom</odometryTopic>
      <odometryFrame>odom</odometryFrame>
      <robotBaseFrame>base_link</robotBaseFrame>
      <broadcastTF>0</broadcastTF>
    </plugin>
  </model>
</sdf>
